Workbook

Sheet PPS
K1: =SUBTOTAL(9,K3:K1048576) -> 36421 | M1: =SUBTOTAL(9,M3:M1048576) -> 2.0191388e+09
A2: Год | B2: Месяц | C2: Дата | D2: Номер СФ | E2: Медпредставитель | F2: Команда | G2: РМ | H2: Поставщик | I2: Название организации | J2: Наименование | K2: Количество | L2: Цена | M2: Сумма | N2: % наценки | O2: Сумма наценки
A3: 2025 | B3: 3 | C3: 45730 | D3: PPS00002118 | E3: Сарварбек ака | F3: Сурхондарьё_Сарвар ака | G3: Азизбек ака | H3: PPS | I3: "Nurbek Layt" Xk | J3: Эльфор р-р. для инф 5м/мл | K3: 40 | L3: 36955.08 | M3: 1478203.2 | N3: 8 | O3: 118256.26
A4: 2025 | B4: 3 | C4: 45743 | D4: PPS00002496 | E4: Нозими опа (Бух) | F4: Бухоро_Рустам ака | G4: Зикрулло ака | H4: PPS | I4: "Diabetes Pharma" Mchj | J4: Эльфор р-р. для инф 5м/мл | K4: 120 | L4: 36955.08 | M4: 4434609.6 | N4: 8 | O4: 354768.77
A5: 2025 | B5: 4 | C5: 45750 | D5: PPS00002647 | E5: Нозими опа (Бух) | F5: Бухоро_Рустам ака | G5: Зикрулло ака | H5: PPS | I5: "IBN SINO" XK | J5: Эльфор р-р. для инф 5м/мл | K5: 30 | L5: 36955.08 | M5: 1108652.4 | N5: 13 | O5: 144124.81
A6: 2025 | B6: 4 | C6: 45751 | D6: PPS00002691 | E6: Рустам ака (Т.О) | F6: Таш,Обл_Рустам ака | G6: Козим ака | H6: PPS | I6: "Farma Com Pro" Mchj | J6: Эльфор р-р. для инф 5м/мл | K6: 20 | L6: 36955.08 | M6: 739101.6 | N6: 15 | O6: 110865.24
A7: 2025 | B7: 4 | C7: 45772 | D7: PPS00003424 | E7: Сарварбек ака | F7: Сурхондарьё_Сарвар ака | G7: Азизбек ака | H7: PPS | I7: Sport Plyus Xk | J7: Эльфор р-р. для инф 5м/мл | K7: 20 | L7: 36955.08 | M7: 739101.6 | N7: 14 | O7: 103474.22
A8: 2025 | B8: 4 | C8: 45776 | D8: PPS00003544 | E8: Хуршид Ака 3 (Сам) | F8: Самарканд_Хуршед ака | G8: Алишер | H8: PPS | I8: "Star Asadbek" Mchj | J8: Эльфор р-р. для инф 5м/мл | K8: 100 | L8: 36955.08 | M8: 3695508 | N8: 15 | O8: 554326.2
A9: 2025 | B9: 4 | C9: 45776 | D9: PPS00003551 | E9: Сарварбек ака | F9: Сурхондарьё_Сарвар ака | G9: Азизбек ака | H9: PPS | I9: "Nurbek Layt" Xk | J9: Эльфор р-р. для инф 5м/мл | K9: 50 | L9: 36955.08 | M9: 1847754 | N9: 8 | O9: 147820.32
A10: 2025 | B10: 5 | C10: 45779 | D10: PPS00003627 | E10: Рустам ака (Т.О) | F10: Таш,Обл_Рустам ака | G10: Козим ака | H10: PPS | I10: "Farma Com Pro" Mchj | J10: Эльфор р-р. для инф 5м/мл | K10: 42 | L10: 36955.08 | M10: 1552113.4 | N10: 10 | O10: 155211.34
A11: 2025 | B11: 5 | C11: 45783 | D11: PPS00003759 | E11: Нозими опа (Бух) | F11: Бухоро_Рустам ака | G11: Зикрулло ака | H11: PPS | I11: "Buxoro Dori Darmon" Mchj | J11: Эльфор р-р. для инф 5м/мл | K11: 1500 | L11: 36955.08 | M11: 55432620 | N11: 8 | O11: 4434609.6
A12: 2025 | B12: 5 | C12: 45783 | D12: PPS00003759 | E12: Нозими опа (Бух) | F12: Бухоро_Рустам ака | G12: Зикрулло ака | H12: PPS | I12: "Buxoro Dori Darmon" Mchj | J12: Эльфор р-р. для инф 5м/мл | K12: 1500 | L12: 36955.08 | M12: 55432620 | N12: 8 | O12: 4434609.6
A13: 2025 | B13: 5 | C13: 45805 | D13: PPS00004467 | E13: Абдушукур ака (Сир) | F13: Сирдарё_Фотима опа | G13: Алишер | H13: PPS | I13: ЧП "Aju-Biznes-Star" | J13: Эльфор р-р. для инф 5м/мл | K13: 40 | L13: 36955.08 | M13: 1478203.2 | N13: 13 | O13: 192166.42
A14: 2025 | B14: 6 | C14: 45812 | D14: PPS00004665 | E14: Фотима опа (Сир) | F14: Сирдарё_Фотима опа | G14: Алишер | H14: PPS | I14: MCHJ Asad Jahongir Farm | J14: Эльфор р-р. для инф 5м/мл | K14: 500 | L14: 36955.08 | M14: 18477540 | N14: 15 | O14: 2771631
... A624: 2026 | B624: 5 | C624: 46157 | D624: PPS00004515 | E624: Анвар ака (Срд) | F624: Сурхондарьё_Анвар ака | G624: Алишер | H624: PPS | I624: "Sariosiyo Xusan Farm" Xk | J624: Эпсол раствор для инфузий 12 мг/мл 50 мл | K624: 18 | L624: 65000 | M624: 1170000 | N624: 15 | O624: 175500

Sheet IPS
K1: =SUBTOTAL(9,K3:K1048576) -> 11777 | M1: =SUBTOTAL(9,M3:M1048576) -> 7.1832483e+08
A2: Год | B2: Месяц | C2: Дата | D2: Номер СФ | E2: Медпредставитель | F2: Команда | G2: РМ | H2: Поставщик | I2: Название организации | J2: Наименование | K2: Количество | L2: Цена | M2: Сумма | N2: % наценки | O2: Сумма наценки
A3: 2025 | B3: 3 | C3: 45721 | D3: GB000000662 | E3: Фотима опа | F3: Сирдарьё_Фотима Опа | G3: Козим ака | H3: GB | I3: "Ozodbek-Yan-Farm" Xk | J3: Эльфор р-р. для инф 5м/мл | K3: 20 | L3: 36955.08 | M3: 739101.6 | N3: 15 | O3: 110865.24
A4: 2025 | B4: 3 | C4: 45728 | D4: GB000000733 | E4: Фотима опа | F4: Сирдарьё_Фотима Опа | G4: Козим ака | H4: GB | I4: "Behzod-Farm-Yangiyer" Mchj | J4: Эльфор р-р. для инф 5м/мл | K4: 30 | L4: 36955.08 | M4: 1108652.4 | N4: 15 | O4: 166297.86
A5: 2025 | B5: 3 | C5: 45733 | D5: GB000000770 | E5: Фотима опа | F5: Сирдарьё_Фотима Опа | G5: Козим ака | H5: GB | I5: "Baxtiyor Turg'unovich" Ktxf | J5: Эльфор р-р. для инф 5м/мл | K5: 60 | L5: 36955.08 | M5: 2217304.8 | N5: 15 | O5: 332595.72
A6: 2025 | B6: 3 | C6: 45733 | D6: GB000000776 | E6: Фотима опа | F6: Сирдарьё_Фотима Опа | G6: Козим ака | H6: GB | I6: "Ozodbek-Yan-Farm" Xk | J6: Эльфор р-р. для инф 5м/мл | K6: 50 | L6: 36955.08 | M6: 1847754 | N6: 15 | O6: 277163.1
A7: 2025 | B7: 4 | C7: 45749 | D7: GB000000922 | E7: Фотима опа | F7: Сирдарьё_Фотима Опа | G7: Козим ака | H7: GB | I7: Asad Jahongir Farm Mchj | J7: Эльфор р-р. для инф 5м/мл | K7: 43 | L7: 36955.08 | M7: 1589068.4 | N7: 15 | O7: 238360.27
A8: 2025 | B8: 4 | C8: 45751 | D8: GB000000954 | E8: Фотима опа | F8: Сирдарьё_Фотима Опа | G8: Козим ака | H8: GB | I8: "Askarbinka Vitaminka" Mchj | J8: Эльфор р-р. для инф 5м/мл | K8: 50 | L8: 36955.08 | M8: 1847754 | N8: 15 | O8: 277163.1
A9: 2025 | B9: 5 | C9: 45798 | D9: GB000001499 | F9: Тошкент_0 | G9: Козим ака | H9: GB | I9: "Profi Pharm Service" Mchj | J9: Эльфор р-р. для инф 5м/мл | K9: 3827 | L9: 36955.08 | M9: 1.4142709e+08 | N9: 3 | O9: 4242812.7
A10: 2026 | B10: 1 | C10: 46035 | D10: GB000000070 | E10: Дилнавоз опа (Тош) | F10: Ташкент_Дилнавоз опа | G10: Козим ака | H10: GB | I10: "CITY PHARM" mas'uliyati cheklangan jamiyati | J10: Эпсол раствор для инфузий 12 мг/мл 50 мл | K10: 10 | L10: 65000 | M10: 650000 | N10: 5 | O10: 32500
A11: 2026 | B11: 1 | C11: 46036 | D11: GB000000085 | E11: Дилнавоз опа (Тош) | F11: Ташкент_Дилнавоз опа | G11: Козим ака | H11: GB | I11: "Apteka Klassika" Mchj | J11: Миранол раствор для инфузий 50 мл | K11: 40 | L11: 90000 | M11: 3600000 | N11: 5 | O11: 180000
A12: 2026 | B12: 1 | C12: 46036 | D12: GB000000085 | E12: Дилнавоз опа (Тош) | F12: Ташкент_Дилнавоз опа | G12: Козим ака | H12: GB | I12: "Apteka Klassika" Mchj | J12: Эпсол раствор для инфузий 12 мг/мл 50 мл | K12: 20 | L12: 65000 | M12: 1300000 | N12: 5 | O12: 65000
A13: 2026 | B13: 1 | C13: 46036 | D13: GB000000092 | E13: Мехриддин ака (Нав) | F13: Навоий_Мехриддин ака | G13: Козим ака | H13: GB | I13: "Jaxon-Farm-Javohir" Mchj | J13: Ландиос Раствор для инфузий 100мл стеклянные флаконы | K13: 20 | L13: 64700 | M13: 1294000 | N13: 10 | O13: 129400
A14: 2026 | B14: 1 | C14: 46037 | D14: GB000000099 | E14: Дилором опа (Тош) | F14: Ташкент_Дилнавоз опа | G14: Козим ака | H14: GB | I14: "Health Planeta" Mchj | J14: Ландиос Раствор для инфузий 100мл стеклянные флаконы | K14: 10 | L14: 64700 | M14: 647000 | N14: 5 | O14: 32350
A15: 2026 | B15: 1 | C15: 46037 | D15: GB000000099 | E15: Дилором опа (Тош) | F15: Ташкент_Дилнавоз опа | G15: Козим ака | H15: GB | I15: "Health Planeta" Mchj | J15: Эпсол раствор для инфузий 12 мг/мл 50 мл | K15: 20 | L15: 65000 | M15: 1300000 | N15: 5 | O15: 65000
A16: 2026 | B16: 1 | C16: 46037 | D16: GB000000100 | E16: Дилнавоз опа (Тош) | F16: Ташкент_Дилнавоз опа | G16: Козим ака | H16: GB | I16: "Prosperiti-Farm" Mchj | J16: Миранол раствор для инфузий 50 мл | K16: 10 | L16: 90000 | M16: 900000 | N16: 5 | O16: 45000
A17: 2026 | B17: 1 | C17: 46037 | D17: GB000000103 | E17: Дилором опа (Тош) | F17: Ташкент_Дилнавоз опа | G17: Козим ака | H17: GB | I17: "Farhod Buyuk Farm" Mchj | J17: Эпсол раствор для инфузий 12 мг/мл 50 мл | K17: 50 | L17: 65000 | M17: 3250000 | N17: 5 | O17: 162500
A18: 2026 | B18: 1 | C18: 46038 | D18: GB000000108 | E18: Дилором опа (Тош) | F18: Ташкент_Дилнавоз опа | G18: Козим ака | H18: GB | I18: "Shifo-Pharm 111" Mchj | J18: Эпсол раствор для инфузий 12 мг/мл 50 мл | K18: 32 | L18: 65000 | M18: 2080000 | N18: 5 | O18: 104000
A19: 2026 | B19: 1 | C19: 46038 | D19: GB000000108 | E19: Дилором опа (Тош) | F19: Ташкент_Дилнавоз опа | G19: Козим ака | H19: GB | I19: "Shifo-Pharm 111" Mchj | J19: Ландиос Раствор для инфузий 100мл стеклянные флаконы | K19: 20 | L19: 64700 | M19: 1294000 | N19: 5 | O19: 64700
A20: 2026 | B20: 1 | C20: 46038 | D20: GB000000122 | F20: Ташкент_Дилнавоз опа | G20: Козим ака | H20: GB | I20: "Umar Fayz Farm" Mchj | J20: Эпсол раствор для инфузий 12 мг/мл 50 мл | K20: 10 | L20: 65000 | M20: 650000 | N20: 5 | O20: 32500
A21: 2026 | B21: 1 | C21: 46038 | D21: GB000000122 | F21: Ташкент_Дилнавоз опа | G21: Козим ака | H21: GB | I21: "Umar Fayz Farm" Mchj | J21: Миранол раствор для инфузий 50 мл | K21: 10 | L21: 90000 | M21: 900000 | N21: 5 | O21: 45000
A22: 2026 | B22: 1 | C22: 46041 | D22: GB000000125 | E22: Нигора (Тош) | F22: Ташкент_Дилнавоз опа | G22: Козим ака | H22: GB | I22: World Of Medicine Mchj | J22: Эпсол раствор для инфузий 12 мг/мл 50 мл | K22: 50 | L22: 65000 | M22: 3250000 | N22: 5 | O22: 162500
A23: 2026 | B23: 1 | C23: 46041 | D23: GB000000127 | E23: Мехриддин ака (Нав) | F23: Навоий_Мехриддин ака | G23: Козим ака | H23: GB | I23: "Vita Pharm Navoiy" Mchj | J23: Ландиос Раствор для инфузий 100мл стеклянные флаконы | K23: 50 | L23: 64700 | M23: 3235000 | N23: 10 | O23: 323500
A24: 2026 | B24: 1 | C24: 46042 | D24: GB000000143 | E24: Мехриддин ака (Нав) | F24: Навоий_Мехриддин ака | G24: Козим ака | H24: GB | I24: "Navbahor Dori Ta`Minoti" Mchj | J24: Ландиос Раствор для инфузий 100мл стеклянные флаконы | K24: 20 | L24: 64700 | M24: 1294000 | N24: 10 | O24: 129400
A25: 2026 | B25: 1 | C25: 46042 | D25: GB000000144 | E25: Нигора (Тош) | F25: Ташкент_Дилнавоз опа | G25: Козим ака | H25: GB | I25: "Ashio Pharm" Mchj | J25: Эпсол раствор для инфузий 12 мг/мл 50 мл | K25: 10 | L25: 65000 | M25: 650000 | N25: 5 | O25: 32500
A26: 2026 | B26: 1 | C26: 46043 | D26: GB000000169 | E26: Ситора опа (Тош) | F26: Ташкент_Дилнавоз опа | G26: Козим ака | H26: GB | I26: "7777 Pharm" Mchj | J26: Ландиос Раствор для инфузий 100мл стеклянные флаконы | K26: 10 | L26: 64700 | M26: 647000 | N26: 5 | O26: 32350
A27: 2026 | B27: 1 | C27: 46043 | D27: GB000000169 | E27: Ситора опа (Тош) | F27: Ташкент_Дилнавоз опа | G27: Козим ака | H27: GB | I27: "7777 Pharm" Mchj | J27: Миранол раствор для инфузий 50 мл | K27: 10 | L27: 90000 | M27: 900000 | N27: 5 | O27: 45000
A28: 2026 | B28: 1 | C28: 46043 | D28: GB000000169 | E28: Ситора опа (Тош) | F28: Ташкент_Дилнавоз опа | G28: Козим ака | H28: GB | I28: "7777 Pharm" Mchj | J28: Эпсол раствор для инфузий 12 мг/мл 50 мл | K28: 10 | L28: 65000 | M28: 650000 | N28: 5 | O28: 32500
A29: 2026 | B29: 1 | C29: 46043 | D29: GB000000174 | E29: Дилором опа (Тош) | F29: Ташкент_Дилнавоз опа | G29: Козим ака | H29: GB | I29: "Bio Nur Med" Mchj | J29: Эпсол раствор для инфузий 12 мг/мл 50 мл | K29: 10 | L29: 65000 | M29: 650000 | N29: 5 | O29: 32500
A30: 2026 | B30: 1 | C30: 46043 | D30: GB000000175 | E30: Дилнавоз опа (Тош) | F30: Ташкент_Дилнавоз опа | G30: Козим ака | H30: GB | I30: "Madina Shifo Nur" Mchj | J30: Миранол раствор для инфузий 50 мл | K30: 20 | L30: 90000 | M30: 1800000 | N30: 5 | O30: 90000
A31: 2026 | B31: 1 | C31: 46043 | D31: GB000000175 | E31: Дилнавоз опа (Тош) | F31: Ташкент_Дилнавоз опа | G31: Козим ака | H31: GB | I31: "Madina Shifo Nur" Mchj | J31: Ландиос Раствор для инфузий 100мл стеклянные флаконы | K31: 20 | L31: 64700 | M31: 1294000 | N31: 5 | O31: 64700
A32: 2026 | B32: 1 | C32: 46043 | D32: GB000000175 | E32: Дилнавоз опа (Тош) | F32: Ташкент_Дилнавоз опа | G32: Козим ака | H32: GB | I32: "Madina Shifo Nur" Mchj | J32: Эпсол раствор для инфузий 12 мг/мл 50 мл | K32: 20 | L32: 65000 | M32: 1300000 | N32: 5 | O32: 65000
A33: 2026 | B33: 1 | C33: 46044 | D33: GB000000181 | E33: Дилнавоз опа (Тош) | F33: Ташкент_Дилнавоз опа | G33: Козим ака | H33: GB | I33: "Tosh-Po'lat Pharm" Mchj | J33: Эпсол раствор для инфузий 12 мг/мл 50 мл | K33: 20 | L33: 65000 | M33: 1300000 | N33: 5 | O33: 65000
... A49: 2026 | B49: 1 | C49: 46052 | D49: GB000000281 | E49: Мехриддин ака (Нав) | F49: Навоий_Мехриддин ака | G49: Козим ака | H49: GB | I49: "Fito-Farm-Lek" Mchj | J49: Ландиос Раствор для инфузий 100мл стеклянные флаконы | K49: 10 | L49: 64700 | M49: 647000 | N49: 8 | O49: 51760
A50: 2026 | B50: 2 | C50: 46055 | D50: GB000000297 | F50: Навоий_Мехриддин ака | G50: Козим ака | H50: GB | I50: "Zulfiya Med Farm 77" Xk | J50: Ландиос Раствор для инфузий 100мл стеклянные флаконы | K50: 20 | L50: 64700 | M50: 1294000 | N50: 10 | O50: 129400
A51: 2026 | B51: 2 | C51: 46055 | D51: GB000000297 | F51: Навоий_Мехриддин ака | G51: Козим ака | H51: GB | I51: "Zulfiya Med Farm 77" Xk | J51: Ландиос Раствор для инфузий 100мл стеклянные флаконы | K51: 20 | L51: 64700 | M51: 1294000 | N51: 10 | O51: 129400
A52: 2026 | B52: 2 | C52: 46056 | D52: GB000000300 | E52: Дилнавоз опа (Тош) | F52: Ташкент_Дилнавоз опа | G52: Козим ака | H52: GB | I52: "Tosh-Po'lat Pharm" Mchj | J52: Миранол раствор для инфузий 50 мл | K52: 20 | L52: 90000 | M52: 1800000 | N52: 5 | O52: 90000
A53: 2026 | B53: 2 | C53: 46056 | D53: GB000000300 | E53: Дилнавоз опа (Тош) | F53: Ташкент_Дилнавоз опа | G53: Козим ака | H53: GB | I53: "Tosh-Po'lat Pharm" Mchj | J53: Ландиос Раствор для инфузий 100мл стеклянные флаконы | K53: 30 | L53: 64700 | M53: 1941000 | N53: 5 | O53: 97050
A54: 2026 | B54: 2 | C54: 46056 | D54: GB000000300 | E54: Дилнавоз опа (Тош) | F54: Ташкент_Дилнавоз опа | G54: Козим ака | H54: GB | I54: "Tosh-Po'lat Pharm" Mchj | J54: Эпсол раствор для инфузий 12 мг/мл 50 мл | K54: 20 | L54: 65000 | M54: 1300000 | N54: 5 | O54: 65000
A55: 2026 | B55: 2 | C55: 46056 | D55: GB000000303 | E55: Мехриддин ака (Нав) | F55: Навоий_Мехриддин ака | G55: Козим ака | H55: GB | I55: "Navbahor Dori Ta`Minoti" Mchj | J55: Ландиос Раствор для инфузий 100мл стеклянные флаконы | K55: 20 | L55: 64700 | M55: 1294000 | N55: 10 | O55: 129400
...

Sheet RMF
K1: =SUBTOTAL(9,K3:K1048576) -> 37531 | M1: =SUBTOTAL(9,M3:M1048576) -> 2661520912
A2: Год | B2: Месяц | C2: Дата | D2: Номер СФ | E2: Медпредставитель | F2: Команда | G2: РМ | H2: Поставщик | I2: Название организации | J2: Наименование | K2: Количество | L2: Цена | M2: Сумма | N2: % наценки | O2: Сумма наценки
A3: 2025 | B3: 10 | C3: 45933 | D3: RMF00004990 | E3: Хуршид ака (Сам) | F3: Самарканд_Хуршед ака | G3: Алишер | H3: RMF | I3: "Isayev Farm 777" Mchj | J3: Эльфор р-р. для инф 5м/мл | K3: 100 | L3: 40621 | M3: 4062100 | N3: 15 | O3: 609315
A4: 2025 | B4: 10 | C4: 45933 | D4: RMF00004995 | E4: Хуршид ака (Сам) | F4: Самарканд_Хуршед ака | G4: Алишер | H4: RMF | I4: "Azamat Gold Farm" Mchj | J4: Эльфор р-р. для инф 5м/мл | K4: 30 | L4: 40621 | M4: 1218630 | N4: 15 | O4: 182794.5
A5: 2025 | B5: 10 | C5: 45939 | D5: RMF00005090 | E5: Улугбек ака (Хор) | F5: Хоразм_Улугбек ака | G5: Алишер | H5: RMF | I5: "Intermed Pharmaceutical" Mchj | J5: Эпсол раствор для инфузий 12 мг/мл 50 мл | K5: 100 | L5: 52500 | M5: 5250000 | N5: 12 | O5: 630000
A6: 2025 | B6: 10 | C6: 45939 | D6: RMF00005090 | E6: Улугбек ака (Хор) | F6: Хоразм_Улугбек ака | G6: Алишер | H6: RMF | I6: "Intermed Pharmaceutical" Mchj | J6: Миранол раствор для инфузий 50 мл | K6: 100 | L6: 67600 | M6: 6760000 | N6: 15 | O6: 1014000
A7: 2025 | B7: 10 | C7: 45939 | D7: RMF00005100 | E7: Умар ака (Фр) | F7: Фаргона_Умар ака Сух | G7: Алишер | H7: RMF | I7: "Sezon Ntd" Xk | J7: Эпсол раствор для инфузий 12 мг/мл 50 мл | K7: 10 | L7: 52500 | M7: 525000 | N7: 15 | O7: 78750
A8: 2025 | B8: 10 | C8: 45939 | D8: RMF00005100 | E8: Умар ака (Фр) | F8: Фаргона_Умар ака Сух | G8: Алишер | H8: RMF | I8: "Sezon Ntd" Xk | J8: Миранол раствор для инфузий 50 мл | K8: 30 | L8: 67600 | M8: 2028000 | N8: 15 | O8: 304200
A9: 2025 | B9: 10 | C9: 45940 | D9: RMF00005113 | E9: Фотима опа (Сир) | F9: Сирдарё_Фотима опа | G9: Алишер | H9: RMF | I9: "Rustambek-J.b.b." Xk | J9: Эпсол раствор для инфузий 12 мг/мл 50 мл | K9: 30 | L9: 52500 | M9: 1575000 | N9: 15 | O9: 236250
A10: 2025 | B10: 10 | C10: 45945 | D10: RMF00005164 | E10: Абдушукур ака (Сир) | F10: Сирдарё_Фотима опа | G10: Алишер | H10: RMF | I10: "Baxtiyor Turg'unovich" Ktxf | J10: Софин раствор для инфузий 5% 100 мл | K10: 30 | L10: 120000 | M10: 3600000 | N10: 15 | O10: 540000
A11: 2025 | B11: 10 | C11: 45946 | D11: RMF00005180 | E11: Профи | F11: Профи | G11: Профи | H11: RMF | I11: "Profi Pharm Service" Mchj | J11: Софин раствор для инфузий 5% 100 мл | K11: 500 | L11: 120000 | M11: 60000000 | N11: 2 | O11: 1200000
A12: 2025 | B12: 10 | C12: 45950 | D12: RMF00005213 | E12: Хуршид ака (Сам) | F12: Самарканд_Хуршед ака | G12: Алишер | H12: RMF | I12: "Max Mir Farm777" Mchj | J12: Эльфор р-р. для инф 5м/мл | K12: 200 | L12: 40621 | M12: 8124200 | N12: 15 | O12: 1218630
A13: 2025 | B13: 10 | C13: 45950 | D13: RMF00005223 | E13: Мехрибон опа (Нк) | F13: Нукус_Мехрибон опа | G13: Алишер | H13: RMF | I13: "Mir Apteka" Mchj | J13: Миранол раствор для инфузий 50 мл | K13: 100 | L13: 90000 | M13: 9000000 | N13: 15 | O13: 1350000
A14: 2025 | B14: 10 | C14: 45951 | D14: RMF00005226 | E14: Фотима опа (Сир) | F14: Сирдарё_Фотима опа | G14: Алишер | H14: RMF | I14: "Ozodbek-Yan-Farm" Xk | J14: Софин раствор для инфузий 5% 100 мл | K14: 20 | L14: 120000 | M14: 2400000 | N14: 15 | O14: 360000
... A439: 2026 | B439: 5 | C439: 46148 | D439: RMF00001300 | E439: Профи | F439: Профи | G439: Профи | H439: RMF | I439: "Profi Pharm Service" Mchj | J439: Эпсол раствор для инфузий 12 мг/мл 50 мл | K439: 350 | L439: 65000 | M439: 22750000 | N439: 2 | O439: 455000

Sheet SFM
K1: =SUBTOTAL(9,K3:K1048576) -> 8573 | M1: =SUBTOTAL(9,M3:M1048576) -> 4.2949169e+08
A2: Год | B2: Месяц | C2: Дата | D2: Номер СФ | E2: Медпредставитель | F2: Команда | G2: РМ | H2: Поставщик | I2: Название организации | J2: Наименование | K2: Количество | L2: Цена | M2: Сумма | N2: % наценки | O2: Сумма наценки
A3: 2025 | B3: 4 | C3: 45770 | D3: SM000001337 | E3: PPS | F3: Тошкент_0 | G3: PPS | H3: SM | I3: "Profi Pharm Service" Mchj | J3: Эльфор р-р. для инф 5м/мл | K3: 2040 | L3: 36955.08 | M3: 75388363 | N3: 4 | O3: 3015534.5
A4: 2025 | B4: 5 | C4: 45803 | D4: SM000002015 | E4: Жонибек ака (Анд) | F4: Андижон_Жонибек ака | G4: Козим ака | H4: SM | I4: "Diyora Trade Pharm" Mchj | J4: Эльфор р-р. для инф 5м/мл | K4: 480 | L4: 36955.08 | M4: 17738438 | N4: 4 | O4: 709537.54
A5: 2025 | B5: 5 | C5: 45804 | D5: SM000002037 | E5: Феруза опа (Нам) | F5: Наманган_Розия опа | G5: Зикрулло ака | H5: SM | I5: "Zam-Zam Med Pharm" Mchj | J5: Эльфор р-р. для инф 5м/мл | K5: 300 | L5: 36955.08 | M5: 11086524 | N5: 8 | O5: 886921.92
A6: 2025 | B6: 5 | C6: 45806 | D6: SM000002089 | E6: Жонибек ака (Анд) | F6: <Объект не найден> (12090:95b918c04d74957511eeb48624412fc6) | H6: SM | I6: "Apteka Centr" Mchj | J6: Эльфор р-р. для инф 5м/мл | K6: 120 | L6: 36955.08 | M6: 4434609.6 | N6: 15 | O6: 665191.44
A7: 2025 | B7: 5 | C7: 45806 | D7: SM000002105 | E7: Феруза опа (Нам) | F7: Наманган_Розия опа | G7: Зикрулло ака | H7: SM | I7: "Mabda Healthcare Group" Mchj | J7: Эльфор р-р. для инф 5м/мл | K7: 20 | L7: 36955.08 | M7: 739101.6 | N7: 10 | O7: 73910.16
A8: 2025 | B8: 6 | C8: 45811 | D8: SM000002168 | E8: Феруза опа (Нам) | F8: Наманган_Розия опа | G8: Зикрулло ака | H8: SM | I8: "Aziz Shifo Farm" Ok | J8: Эльфор р-р. для инф 5м/мл | K8: 5 | L8: 36955.08 | M8: 184775.4 | N8: 13 | O8: 24020.8
A9: 2025 | B9: 6 | C9: 45833 | D9: SM000002503 | E9: Феруза опа (Нам) | F9: Наманган_Розия опа | G9: Зикрулло ака | H9: SM | I9: "Grand Pharm Andijon" Mchj | J9: Эльфор р-р. для инф 5м/мл | K9: 96 | L9: 36955.08 | M9: 3547687.7 | N9: 10 | O9: 354768.77
A10: 2025 | B10: 8 | C10: 45880 | D10: SM000003297 | E10: Жонибек ака (Анд) | F10: Андижон_Жонибек ака | G10: Козим ака | H10: SM | I10: "Diyora Trade Pharm" Mchj | J10: Эльфор р-р. для инф 5м/мл | K10: 480 | L10: 36955.08 | M10: 17738438 | N10: 4 | O10: 709537.54
A11: 2025 | B11: 8 | C11: 45888 | D11: SM000003430 | E11: Жонибек ака (Анд) | F11: <Объект не найден> (12090:95b918c04d74957511eeb48624412fc6) | H11: SM | I11: "Apteka Centr" Mchj | J11: Эльфор р-р. для инф 5м/мл | K11: 120 | L11: 36955.08 | M11: 4434609.6 | N11: 15 | O11: 665191.44
A12: 2025 | B12: 8 | C12: 45890 | D12: SM000003458 | E12: Жонибек ака (Анд) | F12: <Объект не найден> (12090:95b918c04d74957511eeb48624412fc6) | H12: SM | I12: "Mumiyo Dorixonalari Tarmog`I" Mchj | J12: Эльфор р-р. для инф 5м/мл | K12: 60 | L12: 36955.08 | M12: 2217304.8 | N12: 15 | O12: 332595.72
A13: 2025 | B13: 9 | C13: 45909 | D13: SM000003697 | E13: Жонибек ака (Анд) | F13: Андижон_Жонибек ака | G13: Козим ака | H13: SM | I13: "Diyora Trade Pharm" Mchj | J13: Эльфор р-р. для инф 5м/мл | K13: 355 | L13: 36955.08 | M13: 13119053 | N13: 4 | O13: 524762.14
A14: 2025 | B14: 9 | C14: 45915 | D14: SM000003798 | E14: Жонибек ака (Анд) | F14: Андижон_Жонибек ака | G14: Козим ака | H14: SM | I14: "Diyora Trade Pharm" Mchj | J14: Эльфор р-р. для инф 5м/мл | K14: 111 | L14: 40621 | M14: 4508931 | N14: 6 | O14: 270535.86
A15: 2025 | B15: 10 | C15: 45937 | D15: SM000004125 | E15: Жонибек ака (Анд) | F15: Андижон_Жонибек ака | G15: Козим ака | H15: SM | I15: "Apteka Centr" Mchj | J15: Эльфор р-р. для инф 5м/мл | K15: 200 | L15: 40621 | M15: 8124200 | N15: 15 | O15: 1218630
A16: 2025 | B16: 10 | C16: 45943 | D16: SM000004221 | E16: Жонибек ака (Анд) | F16: Андижон_Жонибек ака | G16: Козим ака | H16: SM | I16: "Diyora Trade Pharm" Mchj | J16: Эльфор р-р. для инф 5м/мл | K16: 360 | L16: 40621 | M16: 14623560 | N16: 6 | O16: 877413.6
A17: 2025 | B17: 10 | C17: 45952 | D17: SM000004372 | E17: Зулайхо опа (Нам) | F17: Наманган_Зулайхо опа | G17: Зикрулло ака | H17: SM | I17: "Bilolhon Med Farm Servis" Mchj | J17: Эльфор р-р. для инф 5м/мл | K17: 100 | L17: 40621 | M17: 4062100 | N17: 8 | O17: 324968
A18: 2025 | B18: 11 | C18: 45964 | D18: SM000004579 | E18: Зулайхо опа (Нам) | F18: Наманган_Зулайхо опа | G18: Зикрулло ака | H18: SM | I18: "Bilolhon Med Farm Servis" Mchj | J18: Эльфор р-р. для инф 5м/мл | K18: 200 | L18: 40621 | M18: 8124200 | N18: 8 | O18: 649936
A19: 2025 | B19: 11 | C19: 45964 | D19: SM000004579 | E19: Зулайхо опа (Нам) | F19: Наманган_Зулайхо опа | G19: Зикрулло ака | H19: SM | I19: "Bilolhon Med Farm Servis" Mchj | J19: Эльфор р-р. для инф 5м/мл | K19: 4 | L19: 36955.08 | M19: 147820.32 | N19: 8 | O19: 11825.63
A20: 2025 | B20: 11 | C20: 45964 | D20: SM000004586 | E20: Ахроржон ака (Фр) | F20: Фаргона_Ахроржон Ака | G20: Азизбек ака | H20: SM | I20: "Imbex Farm" Mchj | J20: Софин раствор для инфузий 5% 100 мл | K20: 8 | L20: 120000 | M20: 960000 | N20: 13 | O20: 124800
A21: 2025 | B21: 11 | C21: 45968 | D21: SM000004654 | E21: Ахроржон ака (Фр) | F21: Фаргона_Ахроржон Ака | G21: Азизбек ака | H21: SM | I21: "Pharm Gate Group" Mchj | J21: Софин раствор для инфузий 5% 100 мл | K21: 20 | L21: 120000 | M21: 2400000 | N21: 5 | O21: 120000
A22: 2025 | B22: 11 | C22: 45973 | D22: SM000004731 | E22: Ахроржон ака (Фр) | F22: Фаргона_Ахроржон Ака | G22: Азизбек ака | H22: SM | I22: "Rish Farm Medikal" Mchj | J22: Софин раствор для инфузий 5% 100 мл | K22: 2 | L22: 120000 | M22: 240000 | N22: 10 | O22: 24000
A23: 2025 | B23: 11 | C23: 45974 | D23: SM000004769 | E23: Ахроржон ака (Фр) | F23: Фаргона_Ахроржон Ака | G23: Азизбек ака | H23: SM | I23: "Anor Davo Farm" Mchj | J23: Софин раствор для инфузий 5% 100 мл | K23: 10 | L23: 120000 | M23: 1200000 | N23: 13 | O23: 156000
A24: 2025 | B24: 11 | C24: 45975 | D24: SM000004786 | E24: Зулайхо опа (Нам) | F24: Наманган_Зулайхо опа | G24: Зикрулло ака | H24: SM | I24: MCHJ Unf Innovation Farm | J24: Эльфор р-р. для инф 5м/мл | K24: 48 | L24: 40621 | M24: 1949808 | N24: 8 | O24: 155984.64
... A100: 2026 | B100: 5 | C100: 46157 | D100: SM000002468 | E100: Мусабек ака | F100: Кукон_Баходирхон ака | G100: Алишер | H100: SM | I100: "Grand Pharm Fergana" Mchj | J100: Ландиос Раствор для инфузий 100мл стеклянные флаконы | K100: 40 | L100: 64700 | M100: 2588000 | N100: 15 | O100: 388200

Sheet PPS2
K1: =SUBTOTAL(9,K3:K1048576) -> 81627 | M1: =SUBTOTAL(9,M3:M1048576) -> 820347000
A2: Год | B2: Месяц | C2: Дата | D2: Номер СФ | E2: Медпредставитель | F2: Команда | G2: РМ | H2: Поставщик | I2: Название организации | J2: Наименование | K2: Количество | L2: Цена | M2: Сумма
A3: 2025 | B3: 1 | C3: 45688 | D3: P2000000100 | E3: Хуршед ака | F3: Самарканд_Хуршид ака | G3: Зикрулло ака | H3: P2 | I3: Хуршид ака | J3: Эльфор р-р. для инф 5м/мл | K3: 7800 | L3: 16300 | M3: 127140000
A4: 2025 | B4: 1 | C4: 45688 | D4: P2000000101 | E4: Жонибек ака | F4: Андижон_Жонибек ака | G4: Зикрулло ака | H4: P2 | I4: Жонибек ака Андижон | J4: Эльфор р-р. для инф 5м/мл | K4: 5000
A5: 2025 | B5: 2 | C5: 45692 | D5: P2000000115 | E5: Жонибек ака | F5: Андижон_Жонибек ака | G5: Зикрулло ака | H5: P2 | I5: Жонибек ака Андижон | J5: Эльфор р-р. для инф 5м/мл | K5: 3000
A6: 2025 | B6: 2 | C6: 45698 | D6: P2000000139 | E6: Рустам ака | F6: Б2Б-Бухоро_Рустам ака | G6: Зикрулло ака | H6: P2 | I6: Б2Б-Бухоро_Рустам ака | J6: Эльфор р-р. для инф 5м/мл | K6: 5000
A7: 2025 | B7: 2 | C7: 45714 | D7: P2000000194 | E7: Розия опа | F7: Б2Б - Наманган_Розия опа | G7: Зикрулло ака | H7: P2 | I7: Розия опа | J7: Эльфор р-р. для инф 5м/мл | K7: 480
A8: 2025 | B8: 2 | C8: 45714 | D8: P2000000195 | E8: Рустам ака | F8: Таш.Обл_Рустам ака | G8: Зикрулло ака | H8: P2 | I8: Рустам ака Таш обл | J8: Эльфор р-р. для инф 5м/мл | K8: 1200
A9: 2025 | B9: 2 | C9: 45714 | D9: P2000000196 | E9: Фотима опа | F9: Сирдарьё_Фотима опа | H9: P2 | I9: Фотима опа | J9: Эльфор р-р. для инф 5м/мл | K9: 480
A10: 2025 | B10: 3 | C10: 45723 | D10: P2000000243 | E10: Сарвар ака | F10: Сурхондарьё_Сарвар ака | G10: Азизбек ака | H10: P2 | I10: Сарвар ака | J10: Эльфор р-р. для инф 5м/мл | K10: 500
A11: 2025 | B11: 4 | C11: 45768 | D11: P2000000380 | E11: Б2Б - Навоий_Гулшода опа | F11: Б2Б - Навоий_Гулшода опа | G11: Козим ака | H11: P2 | I11: Б2Б - Навоий_Гулшода опа | J11: Эльфор р-р. для инф 5м/мл | K11: 240
A12: 2025 | B12: 4 | C12: 45768 | D12: P2000000381 | E12: Б2Б - Наманган_Розия опа | F12: Б2Б - Наманган_Розия опа | G12: Зикрулло ака | H12: P2 | I12: Б2Б - Наманган_Розия опа | J12: Эльфор р-р. для инф 5м/мл | K12: 500
A13: 2025 | B13: 4 | C13: 45768 | D13: P2000000395 | E13: Сарвар ака | F13: Сурхондарьё_Сарвар ака | G13: Азизбек ака | H13: P2 | I13: Сарвар ака | J13: Эльфор р-р. для инф 5м/мл | K13: 600 | L13: 19000 | M13: 11400000
A14: 2025 | B14: 4 | C14: 45769 | D14: P2000000399 | E14: Б2Б - Хоразм_Саййора опа | F14: Б2Б - Хоразм_Саййора опа | G14: Зикрулло ака | H14: P2 | I14: Б2Б - Хоразм_Саййора опа | J14: Эльфор р-р. для инф 5м/мл | K14: 1200 | L14: 16300 | M14: 19560000
A15: 2025 | B15: 4 | C15: 45770 | D15: P2000000408 | E15: Жонибек ака | F15: Б2Б - Андижон Жонибек | G15: Жонибек ака | H15: P2 | I15: Жонибек ака Андижон | J15: Эльфор р-р. для инф 5м/мл | K15: 1200
A16: 2025 | B16: 4 | C16: 45770 | D16: P2000000409 | E16: Жонибек ака | F16: Б2Б - Андижон Жонибек | G16: Жонибек ака | H16: P2 | I16: Жонибек ака Андижон | J16: Эльфор р-р. для инф 5м/мл | K16: 1200
A17: 2025 | B17: 5 | C17: 45789 | D17: P2000000517 | E17: Нилюфар опа | F17: Кашкадарьё_Нилуфар опа | G17: Зикрулло ака | H17: P2 | I17: Нилюфар опа Карши | J17: Эльфор р-р. для инф 5м/мл | K17: 480
A18: 2025 | B18: 5 | C18: 45796 | D18: P2000000559 | E18: Рустам ака | F18: Б2Б - Тош обл Рустам ока | G18: Козим ака | H18: P2 | I18: Б2Б - Тош обл Рустам ока | J18: Эльфор р-р. для инф 5м/мл | K18: 480
A19: 2025 | B19: 5 | C19: 45799 | D19: P2000000587 | E19: Б2Б - Навоий_Гулшода опа | F19: Б2Б - Навоий_Гулшода опа | G19: Козим ака | H19: P2 | I19: Б2Б - Навоий_Гулшода опа | J19: Эльфор р-р. для инф 5м/мл | K19: 240
A20: 2025 | B20: 6 | C20: 45813 | D20: P2000000667 | E20: Рустам ака | F20: Б2Б - Тош обл Рустам ока | G20: Козим ака | H20: P2 | I20: Б2Б - Тош обл Рустам ока | J20: Эльфор р-р. для инф 5м/мл | K20: 480
A21: 2025 | B21: 6 | C21: 45818 | D21: P2000000683 | E21: Жонибек ака | F21: Андижон_Жонибек ака | G21: Зикрулло ака | H21: P2 | I21: Жонибек ака Андижон | J21: Эльфор р-р. для инф 5м/мл | K21: 1200
A22: 2025 | B22: 6 | C22: 45825 | D22: P2000000728 | E22: Рустам ака | F22: Б2Б - Тош обл Рустам ока | G22: Козим ака | H22: P2 | I22: Б2Б - Тош обл Рустам ока | J22: Эльфор р-р. для инф 5м/мл | K22: 480
A23: 2025 | B23: 6 | C23: 45827 | D23: P2000000748 | E23: Фотима опа | F23: Сирдарьё_Фотима опа | H23: P2 | I23: Фотима опа | J23: Эльфор р-р. для инф 5м/мл | K23: 100
A24: 2025 | B24: 6 | C24: 45828 | D24: P2000000762 | E24: Нилюфар опа | F24: Кашкадарьё_Нилуфар опа | G24: Зикрулло ака | H24: P2 | I24: Нилюфар опа Карши | J24: Эльфор р-р. для инф 5м/мл | K24: 1000
A25: 2025 | B25: 7 | C25: 45845 | D25: P2000000839 | E25: Рустам ака | F25: Таш.Обл_Рустам ака | G25: Зикрулло ака | H25: P2 | I25: Рустам ака Таш обл | J25: Эльфор р-р. для инф 5м/мл | K25: 480
A26: 2025 | B26: 7 | C26: 45845 | D26: P2000000840 | E26: Жонибек ака | F26: Андижон_Жонибек ака | G26: Зикрулло ака | H26: P2 | I26: Жонибек ака Андижон | J26: Эльфор р-р. для инф 5м/мл | K26: 1200
A27: 2025 | B27: 7 | C27: 45846 | D27: P2000000859 | E27: Б2Б - Хоразм_Саййора опа | F27: Б2Б - Хоразм_Саййора опа | G27: Зикрулло ака | H27: P2 | I27: Б2Б - Хоразм_Саййора опа | J27: Эльфор р-р. для инф 5м/мл | K27: 1500 | L27: 16300 | M27: 24450000
A28: 2025 | B28: 7 | C28: 45848 | D28: P2000000874 | E28: Сарвар ака | F28: Сурхондарьё_Сарвар ака | G28: Азизбек ака | H28: P2 | I28: Сарвар ака | J28: Эльфор р-р. для инф 5м/мл | K28: 500 | L28: 19000 | M28: 9500000
A29: 2025 | B29: 7 | C29: 45849 | D29: P2000000886 | E29: Фотима опа | F29: Сирдарьё_Фотима опа | H29: P2 | I29: Фотима опа | J29: Эльфор р-р. для инф 5м/мл | K29: 300
A30: 2025 | B30: 7 | C30: 45849 | D30: P2000000887 | E30: Фотима опа | F30: Сирдарьё_Фотима опа | H30: P2 | I30: Фотима опа | J30: Эльфор р-р. для инф 5м/мл | K30: 200
A31: 2025 | B31: 7 | C31: 45852 | D31: P2000000890 | E31: Нилюфар опа | F31: Кашкадарьё_Нилуфар опа | G31: Зикрулло ака | H31: P2 | I31: Нилюфар опа Карши | J31: Эльфор р-р. для инф 5м/мл | K31: 1000
A32: 2025 | B32: 7 | C32: 45853 | D32: P2000000904 | E32: Жонибек ака | F32: Андижон_Жонибек ака | G32: Зикрулло ака | H32: P2 | I32: Жонибек ака Андижон | J32: Эльфор р-р. для инф 5м/мл | K32: 2400
A33: 2025 | B33: 7 | C33: 45854 | D33: P2000000911 | E33: Рустам ака | F33: Бухоро_Рустам ака | G33: Зикрулло ака | H33: P2 | I33: Рустам ака | J33: Эльфор р-р. для инф 5м/мл | K33: 2000
A34: 2025 | B34: 7 | C34: 45855 | D34: P2000000926 | E34: Рустам ака | F34: Б2Б-Бухоро_Рустам ака | G34: Зикрулло ака | H34: P2 | I34: Б2Б-Бухоро_Рустам ака | J34: Эльфор р-р. для инф 5м/мл | K34: 480
A35: 2025 | B35: 8 | C35: 45875 | D35: P2000001027 | E35: Рустам ака | F35: Б2Б - Тош обл Рустам ока | G35: Козим ака | H35: P2 | I35: Б2Б - Тош обл Рустам ока | J35: Эльфор р-р. для инф 5м/мл | K35: 480
A36: 2025 | B36: 8 | C36: 45877 | D36: P2000001035 | E36: Нилюфар опа | F36: Кашкадарьё_Нилуфар опа | G36: Зикрулло ака | H36: P2 | I36: Нилюфар опа Карши | J36: Эльфор р-р. для инф 5м/мл | K36: 1000
A37: 2025 | B37: 8 | C37: 45884 | D37: P2000001063 | E37: Жонибек ака | F37: Б2Б - Андижон Жонибек | G37: Жонибек ака | H37: P2 | I37: Жонибек ака Андижон | J37: Эльфор р-р. для инф 5м/мл | K37: 720
A38: 2025 | B38: 8 | C38: 45888 | D38: P2000001071 | E38: Фотима опа | F38: Б2Б - Сирдаре Фотима опа | H38: P2 | I38: Фотима опа | J38: Эльфор р-р. для инф 5м/мл | K38: 100
A39: 2025 | B39: 8 | C39: 45889 | D39: P2000001077 | E39: Людмила опа | F39: Сурхондарьё_Людмила опа | G39: Азам ака | H39: P2 | I39: Людмила опа | J39: Эльфор р-р. для инф 5м/мл | K39: 1000 | L39: 18300 | M39: 18300000
A40: 2025 | B40: 8 | C40: 45889 | D40: P2000001085 | E40: Фотима опа | F40: Б2Б - Сирдаре Фотима опа | H40: P2 | I40: Фотима опа | J40: Эльфор р-р. для инф 5м/мл | K40: 100
...

Sheet IPS2
K1: =SUBTOTAL(9,K3:K1048576) -> 970 | M1: =SUBTOTAL(9,M3:M1048576) -> 12070000
A2: Год | B2: Месяц | C2: Дата | D2: Номер СФ | E2: Медпредставитель | F2: Команда | G2: РМ | H2: Поставщик | I2: Название организации | J2: Наименование | K2: Количество | L2: Цена | M2: Сумма
A3: 2025 | B3: 2 | C3: 45698 | D3: IP200000071 | E3: Фотима | F3: Сирдарьё_Фотима опа | G3: Козим ака | H3: IP2 | I3: Фотима опа | J3: Эльфор р-р. для инф 5м/мл | K3: 500
A4: 2025 | B4: 12 | C4: 45994 | D4: IP200000622 | E4: Элдор ака | F4: Ташкент_Дилнавоз опа | G4: Козим ака | H4: IP2 | I4: Элдор ака | J4: Ландиос Раствор для инфузий 100мл стеклянные флаконы | K4: 40
A5: 2025 | B5: 12 | C5: 45994 | D5: IP200000622 | E5: Элдор ака | F5: Ташкент_Дилнавоз опа | G5: Козим ака | H5: IP2 | I5: Элдор ака | J5: Миранол раствор для инфузий 50 мл | K5: 80 | L5: 20000 | M5: 1600000
A6: 2025 | B6: 12 | C6: 45994 | D6: IP200000622 | E6: Элдор ака | F6: Ташкент_Дилнавоз опа | G6: Козим ака | H6: IP2 | I6: Элдор ака | J6: Эпсол раствор для инфузий 12 мг/мл 50 мл | K6: 80 | L6: 16500 | M6: 1320000
A7: 2026 | B7: 1 | C7: 46028 | D7: IP200000003 | E7: Мехриддин ака | F7: Навоий_Мехриддин ака | G7: Козим ака | H7: IP2 | I7: Мехриддин ака | J7: Ландиос Раствор для инфузий 100мл стеклянные флаконы | K7: 20
A8: 2026 | B8: 1 | C8: 46045 | D8: IP200000025 | E8: Элдор ака | F8: Ташкент_Дилнавоз опа | G8: Козим ака | H8: IP2 | I8: Элдор ака | J8: Миранол раствор для инфузий 50 мл | K8: 30 | L8: 40000 | M8: 1200000
A9: 2026 | B9: 1 | C9: 46045 | D9: IP200000025 | E9: Элдор ака | F9: Ташкент_Дилнавоз опа | G9: Козим ака | H9: IP2 | I9: Элдор ака | J9: Эпсол раствор для инфузий 12 мг/мл 50 мл | K9: 20 | L9: 33000 | M9: 660000
A10: 2026 | B10: 1 | C10: 46052 | D10: IP200000041 | E10: Элдор ака | F10: Ташкент_Дилнавоз опа | G10: Козим ака | H10: IP2 | I10: Элдор ака | J10: Миранол раствор для инфузий 50 мл | K10: 20 | L10: 40000 | M10: 800000
A11: 2026 | B11: 2 | C11: 46071 | D11: IP200000093 | E11: Элдор ака | F11: Ташкент_Дилнавоз опа | G11: Козим ака | H11: IP2 | I11: Элдор ака | J11: Эпсол раствор для инфузий 12 мг/мл 50 мл | K11: 40 | L11: 33000 | M11: 1320000
A12: 2026 | B12: 3 | C12: 46094 | D12: IP200000123 | E12: Элдор ака | F12: Ташкент_Дилнавоз опа | G12: Козим ака | H12: IP2 | I12: Элдор ака | J12: Миранол раствор для инфузий 50 мл | K12: 40 | L12: 40000 | M12: 1600000
A13: 2026 | B13: 3 | C13: 46097 | D13: IP200000132 | E13: Элдор ака | F13: Ташкент_Дилнавоз опа | G13: Козим ака | H13: IP2 | I13: Элдор ака | J13: Миранол раствор для инфузий 50 мл | K13: 20 | L13: 40000 | M13: 800000
A14: 2026 | B14: 4 | C14: 46115 | D14: IP200000167 | E14: Элдор ака | F14: Ташкент_Дилнавоз опа | G14: Козим ака | H14: IP2 | I14: Элдор ака | J14: Миранол раствор для инфузий 50 мл | K14: 20 | L14: 40000 | M14: 800000
A15: 2026 | B15: 4 | C15: 46127 | D15: IP200000195 | E15: Элдор ака | F15: Ташкент_Дилнавоз опа | G15: Козим ака | H15: IP2 | I15: Элдор ака | J15: Миранол раствор для инфузий 50 мл | K15: 10 | L15: 40000 | M15: 400000
A16: 2026 | B16: 4 | C16: 46127 | D16: IP200000195 | E16: Элдор ака | F16: Ташкент_Дилнавоз опа | G16: Козим ака | H16: IP2 | I16: Элдор ака | J16: Эпсол раствор для инфузий 12 мг/мл 50 мл | K16: 10 | L16: 33000 | M16: 330000
A17: 2026 | B17: 5 | C17: 46154 | D17: IP200000233 | E17: Элдор ака | F17: Ташкент_Дилнавоз опа | G17: Козим ака | H17: IP2 | I17: Элдор ака | J17: Ландиос Раствор для инфузий 100мл стеклянные флаконы | K17: 40 | L17: 31000 | M17: 1240000

Sheet RMF2
K1: =SUBTOTAL(9,K3:K1048576) -> 43532 | M1: =SUBTOTAL(9,M3:M1048576) -> 1458185300
A2: Год | B2: Месяц | C2: Дата | D2: Номер СФ | E2: Медпредставитель | F2: Команда | G2: РМ | H2: Поставщик | I2: Название организации | J2: Наименование | K2: Количество | L2: Цена | M2: Сумма
A3: 2025 | B3: 10 | C3: 45940 | D3: R2000000374 | E3: Фотима опа | F3: Сирдарё_Фотима опа | G3: Алишер | H3: R2 | I3: Сирдарё_Фотима опа | J3: Софин раствор для инфузий 5% 100 мл | K3: 50 | L3: 50000 | M3: 2500000
A4: 2025 | B4: 10 | C4: 45940 | D4: R2000000374 | E4: Фотима опа | F4: Сирдарё_Фотима опа | G4: Алишер | H4: R2 | I4: Сирдарё_Фотима опа | J4: Эпсол раствор для инфузий 12 мг/мл 50 мл | K4: 50 | L4: 33000 | M4: 1650000
A5: 2025 | B5: 10 | C5: 45943 | D5: R2000000382 | E5: Улугбек ака | F5: Хоразм_Улугбек ака | G5: Алишер | H5: R2 | I5: Хоразм_Улугбек ака | J5: Миранол раствор для инфузий 50 мл | K5: 300 | L5: 38000 | M5: 11400000
A6: 2025 | B6: 10 | C6: 45943 | D6: R2000000382 | E6: Улугбек ака | F6: Хоразм_Улугбек ака | G6: Алишер | H6: R2 | I6: Хоразм_Улугбек ака | J6: Софин раствор для инфузий 5% 100 мл | K6: 300 | L6: 48000 | M6: 14400000
A7: 2025 | B7: 10 | C7: 45944 | D7: R2000000386 | E7: Андижон_Жонибек ака (S) | F7: Андижон_Жонибек ака (S) | G7: Алишер | H7: R2 | I7: Андижон_Жонибек ака (S) | J7: Софин раствор для инфузий 5% 100 мл | K7: 50 | L7: 50000 | M7: 2500000
A8: 2025 | B8: 10 | C8: 45944 | D8: R2000000387 | E8: Анвар ака | F8: Сурхондарьё_Анвар ака | G8: Алишер | H8: R2 | I8: Сурхондарьё_Анвар ака | J8: Софин раствор для инфузий 5% 100 мл | K8: 80 | L8: 50000 | M8: 4000000
A9: 2025 | B9: 10 | C9: 45944 | D9: R2000000387 | E9: Анвар ака | F9: Сурхондарьё_Анвар ака | G9: Алишер | H9: R2 | I9: Сурхондарьё_Анвар ака | J9: Эпсол раствор для инфузий 12 мг/мл 50 мл | K9: 100 | L9: 33000 | M9: 3300000
A10: 2025 | B10: 10 | C10: 45947 | D10: R2000000402 | E10: Умар | F10: Фаргона_Умар ака Сух | G10: Алишер | H10: R2 | I10: Фаргона_Умар ака Сух | J10: Эпсол раствор для инфузий 12 мг/мл 50 мл | K10: 40 | L10: 33000 | M10: 1320000
A11: 2025 | B11: 10 | C11: 45947 | D11: R2000000402 | E11: Умар | F11: Фаргона_Умар ака Сух | G11: Алишер | H11: R2 | I11: Фаргона_Умар ака Сух | J11: Миранол раствор для инфузий 50 мл | K11: 40 | L11: 40000 | M11: 1600000
A12: 2025 | B12: 10 | C12: 45951 | D12: R2000000420 | E12: Фотима опа | F12: Сирдарё_Фотима опа | G12: Алишер | H12: R2 | I12: Сирдарё_Фотима опа | J12: Миранол раствор для инфузий 50 мл | K12: 50 | L12: 40000 | M12: 2000000
A13: 2025 | B13: 10 | C13: 45951 | D13: R2000000422 | E13: Улугбек ака | F13: Хоразм_Улугбек ака | G13: Алишер | H13: R2 | I13: Хоразм_Улугбек ака | J13: Миранол раствор для инфузий 50 мл | K13: 200 | L13: 38000 | M13: 7600000
A14: 2025 | B14: 10 | C14: 45951 | D14: R2000000422 | E14: Улугбек ака | F14: Хоразм_Улугбек ака | G14: Алишер | H14: R2 | I14: Хоразм_Улугбек ака | J14: Софин раствор для инфузий 5% 100 мл | K14: 20 | L14: 48000 | M14: 960000
... A19: 2025 | B19: 10 | C19: 45957 | D19: R2000000438 | E19: Бахром ака | F19: Кукон_Бахромжон ака | G19: Алишер | H19: R2 | I19: Кукон_Бахромжон ака | J19: Софин раствор для инфузий 5% 100 мл | K19: 400 | L19: 50000 | M19: 20000000
A20: 2025 | B20: 10 | C20: 45960 | D20: R2000000450 | E20: ALIYEV KOZIMALI NOSIRALIYEVICH | F20: 11111 | H20: R2 | I20: Фарм фемили | J20: Эпсол раствор для инфузий 12 мг/мл 50 мл | K20: 20
A21: 2025 | B21: 11 | C21: 45964 | D21: R2000000458 | E21: Нукус_Мехрибон опа | F21: Нукус_Мехрибон опа | G21: Алишер | H21: R2 | I21: Нукус_Мехрибон опа | J21: Миранол раствор для инфузий 50 мл | K21: 100 | L21: 40000 | M21: 4000000
A22: 2025 | B22: 11 | C22: 45968 | D22: R2000000475 | E22: Хуршид ака | F22: Самарканд_Хуршед ака | G22: Алишер | H22: R2 | I22: Самарканд_Хуршед ака | J22: Миранол раствор для инфузий 50 мл | K22: 200 | L22: 40000 | M22: 8000000
A23: 2025 | B23: 11 | C23: 45971 | D23: R2000000482 | E23: Улугбек ака | F23: Хоразм_Улугбек ака | G23: Алишер | H23: R2 | I23: Хоразм_Улугбек ака | J23: Ландиос Раствор для инфузий 100мл стеклянные флаконы | K23: 600 | L23: 31000 | M23: 18600000
A24: 2025 | B24: 11 | C24: 45971 | D24: R2000000483 | E24: Гулшода опа | F24: Навоий_Гулшода опа | G24: Алишер | H24: R2 | I24: Навоий_Гулшода опа (S) | J24: Эпсол раствор для инфузий 12 мг/мл 50 мл | K24: 50 | L24: 33000 | M24: 1650000
A25: 2025 | B25: 11 | C25: 45972 | D25: R2000000485 | E25: Андижон_Жонибек ака (S) | F25: Андижон_Жонибек ака (S) | G25: Алишер | H25: R2 | I25: Андижон_Жонибек ака (S) | J25: Ландиос Раствор для инфузий 100мл стеклянные флаконы | K25: 200 | L25: 31000 | M25: 6200000
A26: 2025 | B26: 11 | C26: 45972 | D26: R2000000485 | E26: Андижон_Жонибек ака (S) | F26: Андижон_Жонибек ака (S) | G26: Алишер | H26: R2 | I26: Андижон_Жонибек ака (S) | J26: Эпсол раствор для инфузий 12 мг/мл 50 мл | K26: 100 | L26: 33000 | M26: 3300000
A27: 2025 | B27: 11 | C27: 45972 | D27: R2000000492 | E27: Хуршид ака | F27: Самарканд_Хуршед ака | G27: Алишер | H27: R2 | I27: Самарканд_Хуршед ака | J27: Софин раствор для инфузий 5% 100 мл | K27: 80 | L27: 50000 | M27: 4000000
A28: 2025 | B28: 11 | C28: 45972 | D28: R2000000494 | E28: Анвар ака | F28: Сурхондарьё_Анвар ака | G28: Алишер | H28: R2 | I28: Сурхондарьё_Анвар ака | J28: Миранол раствор для инфузий 50 мл | K28: 50 | L28: 40000 | M28: 2000000
A29: 2025 | B29: 11 | C29: 45972 | D29: R2000000494 | E29: Анвар ака | F29: Сурхондарьё_Анвар ака | G29: Алишер | H29: R2 | I29: Сурхондарьё_Анвар ака | J29: Эпсол раствор для инфузий 12 мг/мл 50 мл | K29: 100 | L29: 35000 | M29: 3500000
A30: 2025 | B30: 11 | C30: 45973 | D30: R2000000497 | E30: Рустам ака | F30: Таш.Обл_Рустам ака (S) | G30: Алишер | H30: R2 | I30: Таш.Обл_Рустам ака (S) | J30: Миранол раствор для инфузий 50 мл | K30: 400 | L30: 40000 | M30: 16000000
A31: 2025 | B31: 11 | C31: 45973 | D31: R2000000497 | E31: Рустам ака | F31: Таш.Обл_Рустам ака (S) | G31: Алишер | H31: R2 | I31: Таш.Обл_Рустам ака (S) | J31: Эпсол раствор для инфузий 12 мг/мл 50 мл | K31: 400 | L31: 33000 | M31: 13200000
A32: 2025 | B32: 11 | C32: 45974 | D32: R2000000500 | E32: Зафаржон ака | F32: Фаргона_Зафаржон ака | G32: Алишер | H32: R2 | I32: Фаргона_Зафаржон ака | J32: Ландиос Раствор для инфузий 100мл стеклянные флаконы | K32: 500 | L32: 31000 | M32: 15500000
... A73: 2025 | B73: 12 | C73: 46008 | D73: R2000000642 | E73: Хуршид ака | F73: Самарканд_Хуршед ака | G73: Алишер | H73: R2 | I73: Самарканд_Хуршед ака | J73: Эльфор р-р. для инф 5м/мл | K73: 90 | L73: 16300 | M73: 1467000
A74: 2025 | B74: 12 | C74: 46013 | D74: R2000000648 | E74: ALIYEV KOZIMALI NOSIRALIYEVICH | F74: списание | H74: R2 | I74: Списать | J74: Миранол раствор для инфузий 50 мл | K74: 50
A75: 2025 | B75: 12 | C75: 46013 | D75: R2000000649 | E75: Гулшода опа | F75: Навоий_Гулшода опа | G75: Алишер | H75: R2 | I75: Навоий_Гулшода опа (S) | J75: Софин раствор для инфузий 5% 100 мл | K75: 100 | L75: 50000 | M75: 5000000
A76: 2025 | B76: 12 | C76: 46014 | D76: R2000000651 | E76: Андижон_Жонибек ака (S) | F76: Андижон_Жонибек ака (S) | G76: Алишер | H76: R2 | I76: Андижон_Жонибек ака (S) | J76: Ландиос Раствор для инфузий 100мл стеклянные флаконы | K76: 40 | L76: 31000 | M76: 1240000
A77: 2025 | B77: 12 | C77: 46015 | D77: R2000000657 | E77: Хуршид ака | F77: Самарканд_Хуршед ака | G77: Алишер | H77: R2 | I77: Самарканд_Хуршед ака | J77: Эпсол раствор для инфузий 12 мг/мл 50 мл | K77: 50 | L77: 33000 | M77: 1650000
A78: 2026 | B78: 1 | C78: 46041 | D78: R2000000008 | E78: Анвар ака | F78: Сурхондарьё_Анвар ака | G78: Алишер | H78: R2 | I78: Сурхондарьё_Анвар ака | J78: Миранол раствор для инфузий 50 мл | K78: 50 | L78: 40000 | M78: 2000000
A79: 2026 | B79: 1 | C79: 46041 | D79: R2000000008 | E79: Анвар ака | F79: Сурхондарьё_Анвар ака | G79: Алишер | H79: R2 | I79: Сурхондарьё_Анвар ака | J79: Софин раствор для инфузий 5% 100 мл | K79: 80 | L79: 50000 | M79: 4000000
A80: 2026 | B80: 1 | C80: 46041 | D80: R2000000008 | E80: Анвар ака | F80: Сурхондарьё_Анвар ака | G80: Алишер | H80: R2 | I80: Сурхондарьё_Анвар ака | J80: Эпсол раствор для инфузий 12 мг/мл 50 мл | K80: 300 | L80: 33000 | M80: 9900000
A81: 2026 | B81: 1 | C81: 46041 | D81: R2000000009 | E81: Умар | F81: Фаргона_Умар ака Сух | G81: Алишер | H81: R2 | I81: Фаргона_Умар ака Сух | J81: Миранол раствор для инфузий 50 мл | K81: 50 | L81: 40000 | M81: 2000000
A82: 2026 | B82: 1 | C82: 46041 | D82: R2000000010 | E82: Хуршид ака | F82: Самарканд_Хуршед ака | G82: Алишер | H82: R2 | I82: Самарканд_Хуршед ака | J82: Софин раствор для инфузий 5% 100 мл | K82: 100 | L82: 50000 | M82: 5000000
A83: 2026 | B83: 1 | C83: 46041 | D83: R2000000010 | E83: Хуршид ака | F83: Самарканд_Хуршед ака | G83: Алишер | H83: R2 | I83: Самарканд_Хуршед ака | J83: Эльфор р-р. для инф 5м/мл | K83: 110 | L83: 16300 | M83: 1793000
A84: 2026 | B84: 1 | C84: 46041 | D84: R2000000013 | E84: Фотима опа | F84: Сирдарё_Фотима опа | G84: Алишер | H84: R2 | I84: Сирдарё_Фотима опа | J84: Эльфор р-р. для инф 5м/мл | K84: 50 | L84: 16300 | M84: 815000
...

Sheet Лист8
A3: Названия строк | B3: Сумма по полю сумма2
A4: Ландиос Раствор для инфузий 100мл стеклянные флаконы | B4: 151273764
A5: Миранол раствор для инфузий 50 мл | B5: 387865700
A6: Софин раствор для инфузий 5% 100 мл | B6: 284491760
A7: Эльфор р-р. для инф 5м/мл | B7: 6.0290864e+08
A8: Эпсол раствор для инфузий 12 мг/мл 50 мл | B8: 258213150
A9: Общий итог | B9: 1.684753e+09

Sheet Приход колва
A1: Приход
A2: 1 Epsol | B2: 17500
A3: 2 Epsol | B3: 16500
A4: Итого | B4: 34000
D5: Возврат
A6: 1 Miranol | B6: 27500 | D6: 0010825 | E6: 14319
A7: 2 Miranol | B7: 16700 | D7: 0010825 | E7: 1205
A8: Итого | B8: 44200 | D8: Итого | E8: 15524
A10: Приход
A11: 1 Sofin | B11: 19684
A12: 2 Sofin | B12: 14695
A13: Итого | B13: 34379
A16: Продажа
A17: 1 Landios | B17: 13400
A18: 2 Landios | B18: 18520
A19: Итого | B19: 31920
D23: =SUM(D25:D29) -> 3098101720
A24: Наименование | B24: Приход итого на Профи склад | C24: Цена завод | D24: Сумма итого
A25: Ландиос Раствор для инфузий 100мл стеклянные флаконы | B25: 31920 | C25: 18000 | D25: =+B25*C25 -> 574560000
A26: Эпсол раствор для инфузий 12 мг/мл 50 мл | B26: 34000 | C26: 20000 | D26: =+B26*C26 -> 680000000
A27: Софин раствор для инфузий 5% 100 мл | B27: 34379 | C27: 25000 | D27: =+B27*C27 -> 859475000
A28: Эльфор р-р. для инф 5м/мл | B28: 103320 | C28: =3696 -> 3696 | D28: =+B28*C28 -> 381870720
A29: Миранол раствор для инфузий 50 мл | B29: 28676 | C29: 21000 | D29: =+B29*C29 -> 602196000

Sheet Продажа 2
L1: =SUBTOTAL(9,L3:L389) -> 3112806200 | N1: =SUBTOTAL(9,N3:N389) -> 2721843000 | O1: =SUBTOTAL(9,O3:O389) -> 390963200
A2: Год | B2: Месяц | C2: Дата | D2: Номер СФ | E2: Медпредставитель | F2: Команда | G2: Поставщик | H2: Название организации | I2: Наименование | J2: Количество | K2: Цена | L2: Сумма | M2: Оплата | N2: Оплата | O2: Остаток долг
A3: 2025 | B3: 1 | C3: 45688 | D3: P2000000100 | E3: Хуршед ака | F3: Самарканд_Хуршид ака | G3: P2 | H3: Хуршид ака | I3: Эльфор р-р. для инф 5м/мл | J3: 7800 | K3: 16300 | L3: 127140000 | M3: 100 | N3: =+L3*M3% -> 127140000 | O3: =L3-N3 -> 0
A4: 2025 | B4: 1 | C4: 45688 | D4: P2000000101 | E4: Жонибек ака | F4: Андижон_Жонибек ака | G4: P2 | H4: Жонибек ака Андижон | I4: Эльфор р-р. для инф 5м/мл | J4: 5000 | K4: 16300 | L4: 81500000 | M4: 100 | N4: =+L4*M4% -> 81500000 | O4: =L4-N4 -> 0
A5: 2025 | B5: 2 | C5: 45692 | D5: P2000000115 | E5: Жонибек ака | F5: Андижон_Жонибек ака | G5: P2 | H5: Жонибек ака Андижон | I5: Эльфор р-р. для инф 5м/мл | J5: 3000 | K5: 16300 | L5: 48900000 | M5: 100 | N5: =+L5*M5% -> 48900000 | O5: =L5-N5 -> 0
A6: 2025 | B6: 2 | C6: 45698 | D6: P2000000139 | E6: Рустам ака | F6: Б2Б-Бухоро_Рустам ака | G6: P2 | H6: Б2Б-Бухоро_Рустам ака | I6: Эльфор р-р. для инф 5м/мл | J6: 5000 | K6: 18300 | L6: 91500000 | M6: 100 | N6: =+L6*M6% -> 91500000 | O6: =L6-N6 -> 0
A7: 2025 | B7: 2 | C7: 45714 | D7: P2000000194 | E7: Розия опа | F7: Б2Б - Наманган_Розия опа | G7: P2 | H7: Розия опа | I7: Эльфор р-р. для инф 5м/мл | J7: 480 | K7: 18300 | L7: 8784000 | M7: 100 | N7: =+L7*M7% -> 8784000 | O7: =L7-N7 -> 0
A8: 2025 | B8: 2 | C8: 45714 | D8: P2000000195 | E8: Рустам ака | F8: Таш.Обл_Рустам ака | G8: P2 | H8: Рустам ака Таш обл | I8: Эльфор р-р. для инф 5м/мл | J8: 1200 | K8: 18300 | L8: 21960000 | M8: 100 | N8: =+L8*M8% -> 21960000 | O8: =L8-N8 -> 0
A9: 2025 | B9: 2 | C9: 45714 | D9: P2000000196 | E9: Фотима опа | F9: Сирдарьё_Фотима опа | G9: P2 | H9: Фотима опа | I9: Эльфор р-р. для инф 5м/мл | J9: 480 | K9: 18300 | L9: 8784000 | M9: 100 | N9: =+L9*M9% -> 8784000 | O9: =L9-N9 -> 0
A10: 2025 | B10: 3 | C10: 45723 | D10: P2000000243 | E10: Сарвар ака | F10: Сурхондарьё_Сарвар ака | G10: P2 | H10: Сарвар ака | I10: Эльфор р-р. для инф 5м/мл | J10: 500 | K10: 18300 | L10: 9150000 | M10: 100 | N10: =+L10*M10% -> 9150000 | O10: =L10-N10 -> 0
A11: 2025 | B11: 4 | C11: 45768 | D11: P2000000380 | E11: Б2Б - Навоий_Гулшода опа | F11: Б2Б - Навоий_Гулшода опа | G11: P2 | H11: Б2Б - Навоий_Гулшода опа | I11: Эльфор р-р. для инф 5м/мл | J11: 240 | K11: 18300 | L11: 4392000 | M11: 100 | N11: =+L11*M11% -> 4392000 | O11: =L11-N11 -> 0
A12: 2025 | B12: 4 | C12: 45768 | D12: P2000000381 | E12: Б2Б - Наманган_Розия опа | F12: Б2Б - Наманган_Розия опа | G12: P2 | H12: Б2Б - Наманган_Розия опа | I12: Эльфор р-р. для инф 5м/мл | J12: 500 | K12: 18300 | L12: 9150000 | M12: 100 | N12: =+L12*M12% -> 9150000 | O12: =L12-N12 -> 0
A13: 2025 | B13: 4 | C13: 45768 | D13: P2000000395 | E13: Сарвар ака | F13: Сурхондарьё_Сарвар ака | G13: P2 | H13: Сарвар ака | I13: Эльфор р-р. для инф 5м/мл | J13: 600 | K13: 19000 | L13: 11400000 | M13: 100 | N13: =+L13*M13% -> 11400000 | O13: =L13-N13 -> 0
A14: 2025 | B14: 4 | C14: 45769 | D14: P2000000399 | E14: Б2Б - Хоразм_Саййора опа | F14: Б2Б - Хоразм_Саййора опа | G14: P2 | H14: Б2Б - Хоразм_Саййора опа | I14: Эльфор р-р. для инф 5м/мл | J14: 1200 | K14: 16300 | L14: 19560000 | M14: 100 | N14: =+L14*M14% -> 19560000 | O14: =L14-N14 -> 0
... A388: 2026 | B388: 5 | C388: 46157 | D388: R2000000427 | E388: Фотима опа | F388: Сирдарё_Фотима опа | G388: R2 | H388: Сирдарё_Фотима опа | I388: Эпсол раствор для инфузий 12 мг/мл 50 мл | J388: 50 | K388: 33000 | L388: 1650000 | M388: 0 | N388: =+L388*M388% -> 0 | O388: =L388-N388 -> 1650000

Sheet Продажа Переч
K1: =SUBTOTAL(9,K3:K1048576) -> 62762 | M1: =SUBTOTAL(9,M3:M1048576) -> 3.8928103e+09 | N1: =SUBTOTAL(9,N3:N1048576) -> 1263082000 | O1: 0.18 | P1: =SUBTOTAL(9,P3:P1048576) -> 1.7095572e+09 | R1: =SUBTOTAL(9,R3:R1048576) -> 3.4875598e+09 | S1: =SUBTOTAL(9,S3:S1048576) -> 4.0525045e+08
A2: Год | B2: Месяц | C2: Дата | E2: Номер СФ | F2: Медпредставитель | G2: Команда | H2: Поставщик | I2: Название организации | J2: Наименование | K2: Количество | L2: Цена | M2: Сумма | N2: Разница окр/ | O2: Зп | P2: Сумма Итого расход | Q2: Оплата | R2: Оплата сумма | S2: Остаток долга
A3: 2025 | B3: 3 | C3: 45730 | D3: =+E3&G3 -> PPS00002118Сурхондарьё_Сарвар ака | E3: PPS00002118 | F3: Сарварбек ака | G3: Сурхондарьё_Сарвар ака | H3: PPS | I3: "Nurbek Layt" Xk | J3: Эльфор р-р. для инф 5м/мл | K3: 40 | L3: 36955.08 | M3: 1478203.2 | N3: =+K3*15000 -> 600000 | O3: =+M3*$O$1 -> 266076.58 | P3: =+N3+O3 -> 866076.58 | Q3: 100 | R3: =+M3*Q3% -> 1478203.2 | S3: =M3-R3 -> 0
A4: 2025 | B4: 3 | C4: 45743 | D4: =+E4&G4 -> PPS00002496Бухоро_Рустам ака | E4: PPS00002496 | F4: Нозими опа (Бух) | G4: Бухоро_Рустам ака | H4: PPS | I4: "Diabetes Pharma" Mchj | J4: Эльфор р-р. для инф 5м/мл | K4: 120 | L4: 36955.08 | M4: 4434609.6 | N4: =+K4*15000 -> 1800000 | O4: =+M4*$O$1 -> 798229.73 | P4: =+N4+O4 -> 2598229.7 | Q4: 100 | R4: =+M4*Q4% -> 4434609.6 | S4: =M4-R4 -> 0
A5: 2025 | B5: 4 | C5: 45750 | D5: =+E5&G5 -> PPS00002647Бухоро_Рустам ака | E5: PPS00002647 | F5: Нозими опа (Бух) | G5: Бухоро_Рустам ака | H5: PPS | I5: "IBN SINO" XK | J5: Эльфор р-р. для инф 5м/мл | K5: 30 | L5: 36955.08 | M5: 1108652.4 | N5: =+K5*15000 -> 450000 | O5: =+M5*$O$1 -> 199557.43 | P5: =+N5+O5 -> 649557.43 | Q5: 100 | R5: =+M5*Q5% -> 1108652.4 | S5: =M5-R5 -> 0
A6: 2025 | B6: 4 | C6: 45751 | D6: =+E6&G6 -> PPS00002691Таш,Обл_Рустам ака | E6: PPS00002691 | F6: Рустам ака (Т.О) | G6: Таш,Обл_Рустам ака | H6: PPS | I6: "Farma Com Pro" Mchj | J6: Эльфор р-р. для инф 5м/мл | K6: 20 | L6: 36955.08 | M6: 739101.6 | N6: =+K6*15000 -> 300000 | O6: =+M6*$O$1 -> 133038.29 | P6: =+N6+O6 -> 433038.29 | Q6: 100 | R6: =+M6*Q6% -> 739101.6 | S6: =M6-R6 -> 0
A7: 2025 | B7: 4 | C7: 45772 | D7: =+E7&G7 -> PPS00003424Сурхондарьё_Сарвар ака | E7: PPS00003424 | F7: Сарварбек ака | G7: Сурхондарьё_Сарвар ака | H7: PPS | I7: Sport Plyus Xk | J7: Эльфор р-р. для инф 5м/мл | K7: 20 | L7: 36955.08 | M7: 739101.6 | N7: =+K7*15000 -> 300000 | O7: =+M7*$O$1 -> 133038.29 | P7: =+N7+O7 -> 433038.29 | Q7: 100 | R7: =+M7*Q7% -> 739101.6 | S7: =M7-R7 -> 0
A8: 2025 | B8: 4 | C8: 45776 | D8: =+E8&G8 -> PPS00003544Самарканд_Хуршед ака | E8: PPS00003544 | F8: Хуршид Ака 3 (Сам) | G8: Самарканд_Хуршед ака | H8: PPS | I8: "Star Asadbek" Mchj | J8: Эльфор р-р. для инф 5м/мл | K8: 100 | L8: 36955.08 | M8: 3695508 | N8: =+K8*15000 -> 1500000 | O8: =+M8*$O$1 -> 665191.44 | P8: =+N8+O8 -> 2165191.4 | Q8: 100 | R8: =+M8*Q8% -> 3695508 | S8: =M8-R8 -> 0
A9: 2025 | B9: 4 | C9: 45776 | D9: =+E9&G9 -> PPS00003551Сурхондарьё_Сарвар ака | E9: PPS00003551 | F9: Сарварбек ака | G9: Сурхондарьё_Сарвар ака | H9: PPS | I9: "Nurbek Layt" Xk | J9: Эльфор р-р. для инф 5м/мл | K9: 50 | L9: 36955.08 | M9: 1847754 | N9: =+K9*15000 -> 750000 | O9: =+M9*$O$1 -> 332595.72 | P9: =+N9+O9 -> 1082595.7 | Q9: 100 | R9: =+M9*Q9% -> 1847754 | S9: =M9-R9 -> 0
A10: 2025 | B10: 5 | C10: 45779 | D10: =+E10&G10 -> PPS00003627Таш,Обл_Рустам ака | E10: PPS00003627 | F10: Рустам ака (Т.О) | G10: Таш,Обл_Рустам ака | H10: PPS | I10: "Farma Com Pro" Mchj | J10: Эльфор р-р. для инф 5м/мл | K10: 42 | L10: 36955.08 | M10: 1552113.4 | N10: =+K10*15000 -> 630000 | O10: =+M10*$O$1 -> 279380.4 | P10: =+N10+O10 -> 909380.4 | Q10: 100 | R10: =+M10*Q10% -> 1552113.4 | S10: =M10-R10 -> 0
A11: 2025 | B11: 5 | C11: 45783 | D11: =+E11&G11 -> PPS00003759Бухоро_Рустам ака | E11: PPS00003759 | F11: Нозими опа (Бух) | G11: Бухоро_Рустам ака | H11: PPS | I11: "Buxoro Dori Darmon" Mchj | J11: Эльфор р-р. для инф 5м/мл | K11: 1500 | L11: 36955.08 | M11: 55432620 | N11: =+K11*15000 -> 22500000 | O11: =+M11*$O$1 -> 9977871.6 | P11: =+N11+O11 -> 32477872 | Q11: 100 | R11: =+M11*Q11% -> 55432620 | S11: =M11-R11 -> 0
A12: 2025 | B12: 5 | C12: 45783 | D12: =+E12&G12 -> PPS00003759Бухоро_Рустам ака | E12: PPS00003759 | F12: Нозими опа (Бух) | G12: Бухоро_Рустам ака | H12: PPS | I12: "Buxoro Dori Darmon" Mchj | J12: Эльфор р-р. для инф 5м/мл | K12: 1500 | L12: 36955.08 | M12: 55432620 | N12: =+K12*15000 -> 22500000 | O12: =+M12*$O$1 -> 9977871.6 | P12: =+N12+O12 -> 32477872 | Q12: 100 | R12: =+M12*Q12% -> 55432620 | S12: =M12-R12 -> 0
A13: 2025 | B13: 5 | C13: 45805 | D13: =+E13&G13 -> PPS00004467Сирдарё_Фотима опа | E13: PPS00004467 | F13: Абдушукур ака (Сир) | G13: Сирдарё_Фотима опа | H13: PPS | I13: ЧП "Aju-Biznes-Star" | J13: Эльфор р-р. для инф 5м/мл | K13: 40 | L13: 36955.08 | M13: 1478203.2 | N13: =+K13*15000 -> 600000 | O13: =+M13*$O$1 -> 266076.58 | P13: =+N13+O13 -> 866076.58 | Q13: 100 | R13: =+M13*Q13% -> 1478203.2 | S13: =M13-R13 -> 0
A14: 2025 | B14: 6 | C14: 45812 | D14: =+E14&G14 -> PPS00004665Сирдарё_Фотима опа | E14: PPS00004665 | F14: Фотима опа (Сир) | G14: Сирдарё_Фотима опа | H14: PPS | I14: MCHJ Asad Jahongir Farm | J14: Эльфор р-р. для инф 5м/мл | K14: 500 | L14: 36955.08 | M14: 18477540 | N14: =+K14*15000 -> 7500000 | O14: =+M14*$O$1 -> 3325957.2 | P14: =+N14+O14 -> 10825957 | Q14: 100 | R14: =+M14*Q14% -> 18477540 | S14: =M14-R14 -> 0
... A110: 2025 | B110: 10 | C110: 45947 | D110: =+E110&G110 -> PPS00008650Сурхондарьё_Сарвар ака | E110: PPS00008650 | F110: Сарвар ака (Срх) | G110: Сурхондарьё_Сарвар ака | H110: PPS | I110: "Sevara-Bio-Farm" Xk | J110: Эльфор р-р. для инф 5м/мл | K110: 60 | L110: 40621 | M110: 2437260 | N110: =+K110*15000 -> 900000 | O110: =+M110*$O$1 -> 438706.8 | P110: =+N110+O110 -> 1338706.8 | Q110: 100 | R110: =+M110*Q110% -> 2437260 | S110: =M110-R110 -> 0
A111: 2025 | B111: 10 | C111: 45947 | D111: =+E111&G111 -> PPS00008654Таш.Обл_Шахло опа | E111: PPS00008654 | F111: Шахло опа (Т.О) | G111: Таш.Обл_Шахло опа | H111: PPS | I111: "LIR" XK | J111: Софин раствор для инфузий 5% 100 мл | K111: 40 | L111: 120000 | M111: 4800000 | N111: =+K111*35000 -> 1400000 | O111: =+M111*$O$1 -> 864000 | P111: =+N111+O111 -> 2264000 | Q111: 100 | R111: =+M111*Q111% -> 4800000 | S111: =M111-R111 -> 0
A112: 2025 | B112: 10 | C112: 45950 | D112: =+E112&G112 -> PPS00008704Навоий_Дильноза опа | E112: PPS00008704 | F112: Рано опа (Нав) | G112: Навоий_Дильноза опа | H112: PPS | I112: "Grand-Medikal Center" Mchj | J112: Эльфор р-р. для инф 5м/мл | K112: 100 | L112: 40621 | M112: 4062100 | N112: =+K112*15000 -> 1500000 | O112: =+M112*$O$1 -> 731178 | P112: =+N112+O112 -> 2231178 | Q112: 100 | R112: =+M112*Q112% -> 4062100 | S112: =M112-R112 -> 0
A113: 2025 | B113: 10 | C113: 45950 | D113: =+E113&G113 -> PPS00008717Навоий_Дильноза опа | E113: PPS00008717 | F113: Рано опа (Нав) | G113: Навоий_Дильноза опа | H113: PPS | I113: "Navoiy Ultra Diagnostika" Mchj | J113: Эльфор р-р. для инф 5м/мл | K113: 25 | L113: 40621 | M113: 1015525 | N113: =+K113*15000 -> 375000 | O113: =+M113*$O$1 -> 182794.5 | P113: =+N113+O113 -> 557794.5 | Q113: 100 | R113: =+M113*Q113% -> 1015525 | S113: =M113-R113 -> 0
A114: 2025 | B114: 10 | C114: 45950 | D114: =+E114&G114 -> PPS00008738Тошкент_Мохира опа | E114: PPS00008738 | F114: Камола опа (Тош) | G114: Тошкент_Мохира опа | H114: PPS | I114: "Pharzam Pharm" Mchj | J114: Эльфор р-р. для инф 5м/мл | K114: 50 | L114: 40621 | M114: 2031050 | N114: =+K114*15000 -> 750000 | O114: =+M114*$O$1 -> 365589 | P114: =+N114+O114 -> 1115589 | Q114: 100 | R114: =+M114*Q114% -> 2031050 | S114: =M114-R114 -> 0
A115: 2025 | B115: 10 | C115: 45951 | D115: =+E115&G115 -> PPS00008752Тошкент_Мохира опа | E115: PPS00008752 | F115: Дурдона опа (Тош) | G115: Тошкент_Мохира опа | H115: PPS | I115: "Super Pharm" Mchj | J115: Эльфор р-р. для инф 5м/мл | K115: 50 | L115: 40621 | M115: 2031050 | N115: =+K115*15000 -> 750000 | O115: =+M115*$O$1 -> 365589 | P115: =+N115+O115 -> 1115589 | Q115: 100 | R115: =+M115*Q115% -> 2031050 | S115: =M115-R115 -> 0
A116: 2025 | B116: 10 | C116: 45951 | D116: =+E116&G116 -> PPS00008769Шахрисабз_Мафтуна опа | E116: PPS00008769 | F116: Чарос опа (Шах) | G116: Шахрисабз_Мафтуна опа | H116: PPS | I116: "TURDI RASULOVICH" XK | J116: Софин раствор для инфузий 5% 100 мл | K116: 100 | L116: 120000 | M116: 12000000 | N116: =+K116*35000 -> 3500000 | O116: =+M116*$O$1 -> 2160000 | P116: =+N116+O116 -> 5660000 | Q116: 100 | R116: =+M116*Q116% -> 12000000 | S116: =M116-R116 -> 0
A117: 2025 | B117: 10 | C117: 45951 | D117: =+E117&G117 -> PPS00008784Таш.Обл_Шахло опа | E117: PPS00008784 | F117: Шахло опа (Т.О) | G117: Таш.Обл_Шахло опа | H117: PPS | I117: ООО "Lukmoni-Xakim" | J117: Софин раствор для инфузий 5% 100 мл | K117: 20 | L117: 120000 | M117: 2400000 | N117: =+K117*35000 -> 700000 | O117: =+M117*$O$1 -> 432000 | P117: =+N117+O117 -> 1132000 | Q117: 100 | R117: =+M117*Q117% -> 2400000 | S117: =M117-R117 -> 0
A118: 2025 | B118: 10 | C118: 45953 | D118: =+E118&G118 -> PPS00008836Жиззах_Саодат опа | E118: PPS00008836 | F118: Дилноза опа (Жиз) | G118: Жиззах_Саодат опа | H118: PPS | I118: "Omad Sahovat Farm" Xk | J118: Эльфор р-р. для инф 5м/мл | K118: 30 | L118: 40621 | M118: 1218630 | N118: =+K118*15000 -> 450000 | O118: =+M118*$O$1 -> 219353.4 | P118: =+N118+O118 -> 669353.4 | Q118: 100 | R118: =+M118*Q118% -> 1218630 | S118: =M118-R118 -> 0
A119: 2025 | B119: 10 | C119: 45953 | D119: =+E119&G119 -> PPS00008867Самарканд_Хуршед ака | E119: PPS00008867 | F119: Хуршид Ака 3 (Сам) | G119: Самарканд_Хуршед ака | H119: PPS | I119: "Benevitta" Mchj | J119: Софин раствор для инфузий 5% 100 мл | K119: 120 | L119: 120000 | M119: 14400000 | N119: =+K119*35000 -> 4200000 | O119: =+M119*$O$1 -> 2592000 | P119: =+N119+O119 -> 6792000 | Q119: 100 | R119: =+M119*Q119% -> 14400000 | S119: =M119-R119 -> 0
A120: 2025 | B120: 10 | C120: 45953 | D120: =+E120&G120 -> PPS00008871Жиззах_Саодат опа | E120: PPS00008871 | F120: Дилноза опа (Жиз) | G120: Жиззах_Саодат опа | H120: PPS | I120: "Akobir Pharm 444" Mchj | J120: Эльфор р-р. для инф 5м/мл | K120: 48 | L120: 40621 | M120: 1949808 | N120: =+K120*15000 -> 720000 | O120: =+M120*$O$1 -> 350965.44 | P120: =+N120+O120 -> 1070965.4 | Q120: 100 | R120: =+M120*Q120% -> 1949808 | S120: =M120-R120 -> 0
